Workbook

Sheet Summary
A1: Training Log Summary — Run 2 Only
A2: Source: output-PROJECT DL.docx training log. The first run was intentionally excluded; all sheets below treat the second run as the only run.
A4: Part | B4: Training / Experiment | C4: Sheet | D4: Epochs | E4: Training Time (min) | F4: Best Val Acc (%) | G4: Best Val Acc Epoch | H4: Best Val Loss | I4: Best Val Loss Epoch | J4: Final Train Loss | K4: Final Val Loss | L4: Final Train Acc (%) | M4: Final Val Acc (%)
A5: 1 | B5: Assignment 3 Replication (Sanity Check) | C5: P1 | D5: =MAX('P1'!$A$6:$A$15) -> 10 | E5: ='P1'!$B$3 -> 0.74 | F5: =MAX('P1'!$E$6:$E$15) -> 57.5 | G5: =INDEX('P1'!$A$6:$A$15,MATCH(MAX('P1'!$E$6:$E$15),'P1'!$E$6:$E$15,0)) -> 4 | H5: =MIN('P1'!$C$6:$C$15) -> 1.2205 | I5: =INDEX('P1'!$A$6:$A$15,MATCH(MIN('P1'!$C$6:$C$15),'P1'!$C$6:$C$15,0)) -> 4 | J5: =INDEX('P1'!$B$6:$B$15,MATCH(MAX('P1'!$A$6:$A$15),'P1'!$A$6:$A$15,0)) -> 1.2256 | K5: =INDEX('P1'!$C$6:$C$15,MATCH(MAX('P1'!$A$6:$A$15),'P1'!$A$6:$A$15,0)) -> 1.3215 | L5: =INDEX('P1'!$D$6:$D$15,MATCH(MAX('P1'!$A$6:$A$15),'P1'!$A$6:$A$15,0)) -> 56.4 | M5: =INDEX('P1'!$E$6:$E$15,MATCH(MAX('P1'!$A$6:$A$15),'P1'!$A$6:$A$15,0)) -> 52.1
A6: 2 | B6: First Upgrade (1 Raw VGG Block - Expect Overfitting) | C6: P2 | D6: =MAX('P2'!$A$6:$A$30) -> 25 | E6: ='P2'!$B$3 -> 3.96 | F6: =MAX('P2'!$E$6:$E$30) -> 72.1 | G6: =INDEX('P2'!$A$6:$A$30,MATCH(MAX('P2'!$E$6:$E$30),'P2'!$E$6:$E$30,0)) -> 7 | H6: =MIN('P2'!$C$6:$C$30) -> 0.8462 | I6: =INDEX('P2'!$A$6:$A$30,MATCH(MIN('P2'!$C$6:$C$30),'P2'!$C$6:$C$30,0)) -> 4 | J6: =INDEX('P2'!$B$6:$B$30,MATCH(MAX('P2'!$A$6:$A$30),'P2'!$A$6:$A$30,0)) -> 0.0675 | K6: =INDEX('P2'!$C$6:$C$30,MATCH(MAX('P2'!$A$6:$A$30),'P2'!$A$6:$A$30,0)) -> 2.4109 | L6: =INDEX('P2'!$D$6:$D$30,MATCH(MAX('P2'!$A$6:$A$30),'P2'!$A$6:$A$30,0)) -> 97.65 | M6: =INDEX('P2'!$E$6:$E$30,MATCH(MAX('P2'!$A$6:$A$30),'P2'!$A$6:$A$30,0)) -> 69.1
A7: 3 | B7: Full Baseline (3 Raw VGG Blocks - Expect Heavy Overfitting) | C7: P3 | D7: =MAX('P3'!$A$6:$A$30) -> 25 | E7: ='P3'!$B$3 -> 20.62 | F7: =MAX('P3'!$E$6:$E$30) -> 76 | G7: =INDEX('P3'!$A$6:$A$30,MATCH(MAX('P3'!$E$6:$E$30),'P3'!$E$6:$E$30,0)) -> 9 | H7: =MIN('P3'!$C$6:$C$30) -> 0.7699 | I7: =INDEX('P3'!$A$6:$A$30,MATCH(MIN('P3'!$C$6:$C$30),'P3'!$C$6:$C$30,0)) -> 6 | J7: =INDEX('P3'!$B$6:$B$30,MATCH(MAX('P3'!$A$6:$A$30),'P3'!$A$6:$A$30,0)) -> 0.0775 | K7: =INDEX('P3'!$C$6:$C$30,MATCH(MAX('P3'!$A$6:$A$30),'P3'!$A$6:$A$30,0)) -> 1.4793 | L7: =INDEX('P3'!$D$6:$D$30,MATCH(MAX('P3'!$A$6:$A$30),'P3'!$A$6:$A$30,0)) -> 97.37 | M7: =INDEX('P3'!$E$6:$E$30,MATCH(MAX('P3'!$A$6:$A$30),'P3'!$A$6:$A$30,0)) -> 73.7
A8: 4a | B8: Dropout ONLY | C8: P4a | D8: =MAX(P4a!$A$6:$A$30) -> 25 | E8: =P4a!$B$3 -> 13.77 | F8: =MAX(P4a!$E$6:$E$30) -> 85.3 | G8: =INDEX(P4a!$A$6:$A$30,MATCH(MAX(P4a!$E$6:$E$30),P4a!$E$6:$E$30,0)) -> 19 | H8: =MIN(P4a!$C$6:$C$30) -> 0.5326 | I8: =INDEX(P4a!$A$6:$A$30,MATCH(MIN(P4a!$C$6:$C$30),P4a!$C$6:$C$30,0)) -> 12 | J8: =INDEX(P4a!$B$6:$B$30,MATCH(MAX(P4a!$A$6:$A$30),P4a!$A$6:$A$30,0)) -> 0.133 | K8: =INDEX(P4a!$C$6:$C$30,MATCH(MAX(P4a!$A$6:$A$30),P4a!$A$6:$A$30,0)) -> 0.6084 | L8: =INDEX(P4a!$D$6:$D$30,MATCH(MAX(P4a!$A$6:$A$30),P4a!$A$6:$A$30,0)) -> 95.4 | M8: =INDEX(P4a!$E$6:$E$30,MATCH(MAX(P4a!$A$6:$A$30),P4a!$A$6:$A$30,0)) -> 85
A9: 4b | B9: L2 Regularization ONLY | C9: P4b | D9: =MAX(P4b!$A$6:$A$30) -> 25 | E9: =P4b!$B$3 -> 25.98 | F9: =MAX(P4b!$E$6:$E$30) -> 82.9 | G9: =INDEX(P4b!$A$6:$A$30,MATCH(MAX(P4b!$E$6:$E$30),P4b!$E$6:$E$30,0)) -> 23 | H9: =MIN(P4b!$C$6:$C$30) -> 0.6186 | I9: =INDEX(P4b!$A$6:$A$30,MATCH(MIN(P4b!$C$6:$C$30),P4b!$C$6:$C$30,0)) -> 5 | J9: =INDEX(P4b!$B$6:$B$30,MATCH(MAX(P4b!$A$6:$A$30),P4b!$A$6:$A$30,0)) -> 0.0297 | K9: =INDEX(P4b!$C$6:$C$30,MATCH(MAX(P4b!$A$6:$A$30),P4b!$A$6:$A$30,0)) -> 1.0391 | L9: =INDEX(P4b!$D$6:$D$30,MATCH(MAX(P4b!$A$6:$A$30),P4b!$A$6:$A$30,0)) -> 98.98 | M9: =INDEX(P4b!$E$6:$E$30,MATCH(MAX(P4b!$A$6:$A$30),P4b!$A$6:$A$30,0)) -> 80.9
A10: 4c | B10: Data Augmentation ONLY | C10: P4c | D10: =MAX(P4c!$A$6:$A$30) -> 25 | E10: =P4c!$B$3 -> 36.08 | F10: =MAX(P4c!$E$6:$E$30) -> 88.4 | G10: =INDEX(P4c!$A$6:$A$30,MATCH(MAX(P4c!$E$6:$E$30),P4c!$E$6:$E$30,0)) -> 25 | H10: =MIN(P4c!$C$6:$C$30) -> 0.3614 | I10: =INDEX(P4c!$A$6:$A$30,MATCH(MIN(P4c!$C$6:$C$30),P4c!$C$6:$C$30,0)) -> 21 | J10: =INDEX(P4c!$B$6:$B$30,MATCH(MAX(P4c!$A$6:$A$30),P4c!$A$6:$A$30,0)) -> 0.2353 | K10: =INDEX(P4c!$C$6:$C$30,MATCH(MAX(P4c!$A$6:$A$30),P4c!$A$6:$A$30,0)) -> 0.3956 | L10: =INDEX(P4c!$D$6:$D$30,MATCH(MAX(P4c!$A$6:$A$30),P4c!$A$6:$A$30,0)) -> 91.73 | M10: =INDEX(P4c!$E$6:$E$30,MATCH(MAX(P4c!$A$6:$A$30),P4c!$A$6:$A$30,0)) -> 88.4
A11: 5 | B11: Combined Regularization (Dropout + L2 + Augmentation + BatchNorm) | C11: P5 | D11: =MAX('P5'!$A$6:$A$55) -> 50 | E11: ='P5'!$B$3 -> 84.13 | F11: =MAX('P5'!$E$6:$E$55) -> 89.7 | G11: =INDEX('P5'!$A$6:$A$55,MATCH(MAX('P5'!$E$6:$E$55),'P5'!$E$6:$E$55,0)) -> 50 | H11: =MIN('P5'!$C$6:$C$55) -> 0.328 | I11: =INDEX('P5'!$A$6:$A$55,MATCH(MIN('P5'!$C$6:$C$55),'P5'!$C$6:$C$55,0)) -> 50 | J11: =INDEX('P5'!$B$6:$B$55,MATCH(MAX('P5'!$A$6:$A$55),'P5'!$A$6:$A$55,0)) -> 0.2787 | K11: =INDEX('P5'!$C$6:$C$55,MATCH(MAX('P5'!$A$6:$A$55),'P5'!$A$6:$A$55,0)) -> 0.328 | L11: =INDEX('P5'!$D$6:$D$55,MATCH(MAX('P5'!$A$6:$A$55),'P5'!$A$6:$A$55,0)) -> 90.43 | M11: =INDEX('P5'!$E$6:$E$55,MATCH(MAX('P5'!$A$6:$A$55),'P5'!$A$6:$A$55,0)) -> 89.7
A12: 6a | B12: Adv. Augmentation (Cut-out + Label Smoothing) | C12: P6a | D12: =MAX(P6a!$A$6:$A$55) -> 50 | E12: =P6a!$B$3 -> 18.88 | F12: =MAX(P6a!$E$6:$E$55) -> 89 | G12: =INDEX(P6a!$A$6:$A$55,MATCH(MAX(P6a!$E$6:$E$55),P6a!$E$6:$E$55,0)) -> 50 | H12: =MIN(P6a!$C$6:$C$55) -> 0.7612 | I12: =INDEX(P6a!$A$6:$A$55,MATCH(MIN(P6a!$C$6:$C$55),P6a!$C$6:$C$55,0)) -> 49 | J12: =INDEX(P6a!$B$6:$B$55,MATCH(MAX(P6a!$A$6:$A$55),P6a!$A$6:$A$55,0)) -> 0.8154 | K12: =INDEX(P6a!$C$6:$C$55,MATCH(MAX(P6a!$A$6:$A$55),P6a!$A$6:$A$55,0)) -> 0.7627 | L12: =INDEX(P6a!$D$6:$D$55,MATCH(MAX(P6a!$A$6:$A$55),P6a!$A$6:$A$55,0)) -> 87.63 | M12: =INDEX(P6a!$E$6:$E$55,MATCH(MAX(P6a!$A$6:$A$55),P6a!$A$6:$A$55,0)) -> 89
A13: 6b | B13: LR Scheduler (Cosine Annealing with Warm Restarts) | C13: P6b | D13: =MAX(P6b!$A$6:$A$55) -> 50 | E13: =P6b!$B$3 -> 47.55 | F13: =MAX(P6b!$E$6:$E$55) -> 90.4 | G13: =INDEX(P6b!$A$6:$A$55,MATCH(MAX(P6b!$E$6:$E$55),P6b!$E$6:$E$55,0)) -> 48 | H13: =MIN(P6b!$C$6:$C$55) -> 0.3041 | I13: =INDEX(P6b!$A$6:$A$55,MATCH(MIN(P6b!$C$6:$C$55),P6b!$C$6:$C$55,0)) -> 48 | J13: =INDEX(P6b!$B$6:$B$55,MATCH(MAX(P6b!$A$6:$A$55),P6b!$A$6:$A$55,0)) -> 0.2603 | K13: =INDEX(P6b!$C$6:$C$55,MATCH(MAX(P6b!$A$6:$A$55),P6b!$A$6:$A$55,0)) -> 0.3053 | L13: =INDEX(P6b!$D$6:$D$55,MATCH(MAX(P6b!$A$6:$A$55),P6b!$A$6:$A$55,0)) -> 91.03 | M13: =INDEX(P6b!$E$6:$E$55,MATCH(MAX(P6b!$A$6:$A$55),P6b!$A$6:$A$55,0)) -> 90.1
A14: 6c | B14: Stride 2 Down-sampling (No MaxPool) | C14: P6c | D14: =MAX(P6c!$A$6:$A$55) -> 50 | E14: =P6c!$B$3 -> 36.45 | F14: =MAX(P6c!$E$6:$E$55) -> 88.8 | G14: =INDEX(P6c!$A$6:$A$55,MATCH(MAX(P6c!$E$6:$E$55),P6c!$E$6:$E$55,0)) -> 45 | H14: =MIN(P6c!$C$6:$C$55) -> 0.3446 | I14: =INDEX(P6c!$A$6:$A$55,MATCH(MIN(P6c!$C$6:$C$55),P6c!$C$6:$C$55,0)) -> 45 | J14: =INDEX(P6c!$B$6:$B$55,MATCH(MAX(P6c!$A$6:$A$55),P6c!$A$6:$A$55,0)) -> 0.3314 | K14: =INDEX(P6c!$C$6:$C$55,MATCH(MAX(P6c!$A$6:$A$55),P6c!$A$6:$A$55,0)) -> 0.3622 | L14: =INDEX(P6c!$D$6:$D$55,MATCH(MAX(P6c!$A$6:$A$55),P6c!$A$6:$A$55,0)) -> 88.52 | M14: =INDEX(P6c!$E$6:$E$55,MATCH(MAX(P6c!$A$6:$A$55),P6c!$A$6:$A$55,0)) -> 88.5
A15: 6d | B15: Global Average Pooling (Replacing FC Layer) | C15: P6d | D15: =MAX(P6d!$A$6:$A$55) -> 50 | E15: =P6d!$B$3 -> 22.9 | F15: =MAX(P6d!$E$6:$E$55) -> 90.1 | G15: =INDEX(P6d!$A$6:$A$55,MATCH(MAX(P6d!$E$6:$E$55),P6d!$E$6:$E$55,0)) -> 46 | H15: =MIN(P6d!$C$6:$C$55) -> 0.3299 | I15: =INDEX(P6d!$A$6:$A$55,MATCH(MIN(P6d!$C$6:$C$55),P6d!$C$6:$C$55,0)) -> 40 | J15: =INDEX(P6d!$B$6:$B$55,MATCH(MAX(P6d!$A$6:$A$55),P6d!$A$6:$A$55,0)) -> 0.2441 | K15: =INDEX(P6d!$C$6:$C$55,MATCH(MAX(P6d!$A$6:$A$55),P6d!$A$6:$A$55,0)) -> 0.3608 | L15: =INDEX(P6d!$D$6:$D$55,MATCH(MAX(P6d!$A$6:$A$55),P6d!$A$6:$A$55,0)) -> 91.23 | M15: =INDEX(P6d!$E$6:$E$55,MATCH(MAX(P6d!$A$6:$A$55),P6d!$A$6:$A$55,0)) -> 89.5

Sheet All_Data
A1: All Epoch Data — Run 2 Only
A3: Part | B3: Training / Experiment | C3: Epoch | D3: Train Loss | E3: Val Loss | F3: Train Acc (%) | G3: Val Acc (%) | H3: Training Time (min)
A4: 1 | B4: Assignment 3 Replication (Sanity Check) | C4: 1 | D4: 1.8299 | E4: 1.5705 | F4: 34.14 | G4: 43.3 | H4: 0.74
A5: 1 | B5: Assignment 3 Replication (Sanity Check) | C5: 2 | D5: 1.4882 | E5: 1.4521 | F5: 46.8 | G5: 49.7 | H5: 0.74
A6: 1 | B6: Assignment 3 Replication (Sanity Check) | C6: 3 | D6: 1.4004 | E6: 1.3609 | F6: 50.25 | G6: 52.3 | H6: 0.74
A7: 1 | B7: Assignment 3 Replication (Sanity Check) | C7: 4 | D7: 1.2555 | E7: 1.2205 | F7: 55.74 | G7: 57.5 | H7: 0.74
A8: 1 | B8: Assignment 3 Replication (Sanity Check) | C8: 5 | D8: 1.1597 | E8: 1.2726 | F8: 58.92 | G8: 54.8 | H8: 0.74
A9: 1 | B9: Assignment 3 Replication (Sanity Check) | C9: 6 | D9: 1.292 | E9: 1.3617 | F9: 54.11 | G9: 52 | H9: 0.74
A10: 1 | B10: Assignment 3 Replication (Sanity Check) | C10: 7 | D10: 1.3282 | E10: 1.335 | F10: 52.93 | G10: 53.8 | H10: 0.74
A11: 1 | B11: Assignment 3 Replication (Sanity Check) | C11: 8 | D11: 1.215 | E11: 1.2685 | F11: 56.99 | G11: 55.3 | H11: 0.74
A12: 1 | B12: Assignment 3 Replication (Sanity Check) | C12: 9 | D12: 1.0772 | E12: 1.2989 | F12: 62.17 | G12: 54.2 | H12: 0.74
A13: 1 | B13: Assignment 3 Replication (Sanity Check) | C13: 10 | D13: 1.2256 | E13: 1.3215 | F13: 56.4 | G13: 52.1 | H13: 0.74
A14: 2 | B14: First Upgrade (1 Raw VGG Block - Expect Overfitting) | C14: 1 | D14: 1.4305 | E14: 1.1332 | F14: 48.6 | G14: 59.8 | H14: 3.96
A15: 2 | B15: First Upgrade (1 Raw VGG Block - Expect Overfitting) | C15: 2 | D15: 1.0444 | E15: 0.9817 | F15: 62.82 | G15: 64.4 | H15: 3.96
... A388: 6d | B388: Global Average Pooling (Replacing FC Layer) | C388: 50 | D388: 0.2441 | E388: 0.3608 | F388: 91.23 | G388: 89.5 | H388: 22.9

Sheet P1
A1: Part 1: Assignment 3 Replication (Sanity Check)
A2: Part | B2: 1 | C2: Epochs | D2: 10
A3: Training Time (min) | B3: 0.74 | C3: Experiment | D3: Assignment 3 Replication (Sanity Check)
A5: Epoch | B5: Train Loss | C5: Val Loss | D5: Train Acc (%) | E5: Val Acc (%)
A6: 1 | B6: 1.8299 | C6: 1.5705 | D6: 34.14 | E6: 43.3
A7: 2 | B7: 1.4882 | C7: 1.4521 | D7: 46.8 | E7: 49.7
A8: 3 | B8: 1.4004 | C8: 1.3609 | D8: 50.25 | E8: 52.3
A9: 4 | B9: 1.2555 | C9: 1.2205 | D9: 55.74 | E9: 57.5
A10: 5 | B10: 1.1597 | C10: 1.2726 | D10: 58.92 | E10: 54.8
A11: 6 | B11: 1.292 | C11: 1.3617 | D11: 54.11 | E11: 52
A12: 7 | B12: 1.3282 | C12: 1.335 | D12: 52.93 | E12: 53.8
A13: 8 | B13: 1.215 | C13: 1.2685 | D13: 56.99 | E13: 55.3
A14: 9 | B14: 1.0772 | C14: 1.2989 | D14: 62.17 | E14: 54.2
A15: 10 | B15: 1.2256 | C15: 1.3215 | D15: 56.4 | E15: 52.1

Sheet P2
A1: Part 2: First Upgrade (1 Raw VGG Block - Expect Overfitting)
A2: Part | B2: 2 | C2: Epochs | D2: 25
A3: Training Time (min) | B3: 3.96 | C3: Experiment | D3: First Upgrade (1 Raw VGG Block - Expect Overfitting)
A5: Epoch | B5: Train Loss | C5: Val Loss | D5: Train Acc (%) | E5: Val Acc (%)
A6: 1 | B6: 1.4305 | C6: 1.1332 | D6: 48.6 | E6: 59.8
A7: 2 | B7: 1.0444 | C7: 0.9817 | D7: 62.82 | E7: 64.4
A8: 3 | B8: 0.8752 | C8: 0.903 | D8: 68.82 | E8: 69
A9: 4 | B9: 0.7497 | C9: 0.8462 | D9: 73.52 | E9: 70.9
A10: 5 | B10: 0.6479 | C10: 0.8756 | D10: 77.13 | E10: 69.3
A11: 6 | B11: 0.552 | C11: 0.8932 | D11: 80.64 | E11: 69.9
A12: 7 | B12: 0.4671 | C12: 0.9197 | D12: 83.44 | E12: 72.1
A13: 8 | B13: 0.3846 | C13: 1.0161 | D13: 86.34 | E13: 70.7
A14: 9 | B14: 0.303 | C14: 1.125 | D14: 89.27 | E14: 71.1
A15: 10 | B15: 0.2351 | C15: 1.2685 | D15: 91.73 | E15: 70.1
A16: 11 | B16: 0.1911 | C16: 1.314 | D16: 93.11 | E16: 69.3
A17: 12 | B17: 0.1457 | C17: 1.511 | D17: 94.95 | E17: 70.1
... A30: 25 | B30: 0.0675 | C30: 2.4109 | D30: 97.65 | E30: 69.1

Sheet P3
A1: Part 3: Full Baseline (3 Raw VGG Blocks - Expect Heavy Overfitting)
A2: Part | B2: 3 | C2: Epochs | D2: 25
A3: Training Time (min) | B3: 20.62 | C3: Experiment | D3: Full Baseline (3 Raw VGG Blocks - Expect Heavy Overfitting)
A5: Epoch | B5: Train Loss | C5: Val Loss | D5: Train Acc (%) | E5: Val Acc (%)
A6: 1 | B6: 1.7152 | C6: 1.423 | D6: 35.72 | E6: 48.5
A7: 2 | B7: 1.2509 | C7: 1.1785 | D7: 54.33 | E7: 59.5
A8: 3 | B8: 1.0105 | C8: 0.9262 | D8: 63.66 | E8: 66.5
A9: 4 | B9: 0.8647 | C9: 0.8825 | D9: 69.19 | E9: 68.2
A10: 5 | B10: 0.7452 | C10: 0.8411 | D10: 73.66 | E10: 69.8
A11: 6 | B11: 0.6365 | C11: 0.7699 | D11: 77.59 | E11: 72.6
A12: 7 | B12: 0.5396 | C12: 0.8248 | D12: 80.91 | E12: 72.9
A13: 8 | B13: 0.4528 | C13: 0.8074 | D13: 84.17 | E13: 74.4
A14: 9 | B14: 0.3876 | C14: 0.8291 | D14: 86.22 | E14: 76
A15: 10 | B15: 0.2988 | C15: 0.8965 | D15: 89.55 | E15: 75.7
A16: 11 | B16: 0.251 | C16: 0.9545 | D16: 91.13 | E16: 73.9
A17: 12 | B17: 0.1946 | C17: 1.0072 | D17: 93.09 | E17: 74.8
... A30: 25 | B30: 0.0775 | C30: 1.4793 | D30: 97.37 | E30: 73.7

Sheet P4a
A1: Part 4a: Dropout ONLY
A2: Part | B2: 4a | C2: Epochs | D2: 25
A3: Training Time (min) | B3: 13.77 | C3: Experiment | D3: Dropout ONLY
A5: Epoch | B5: Train Loss | C5: Val Loss | D5: Train Acc (%) | E5: Val Acc (%)
A6: 1 | B6: 1.3762 | C6: 1.157 | D6: 50.48 | E6: 59.7
A7: 2 | B7: 0.9783 | C7: 0.8834 | D7: 66.1 | E7: 70.2
A8: 3 | B8: 0.8126 | C8: 0.8373 | D8: 72.15 | E8: 70.1
A9: 4 | B9: 0.7121 | C9: 0.6617 | D9: 75.6 | E9: 77.9
A10: 5 | B10: 0.6305 | C10: 0.5885 | D10: 78.65 | E10: 80.3
A11: 6 | B11: 0.5667 | C11: 0.585 | D11: 80.59 | E11: 81
A12: 7 | B12: 0.515 | C12: 0.587 | D12: 82.71 | E12: 81.4
A13: 8 | B13: 0.463 | C13: 0.5625 | D13: 84.23 | E13: 81.9
A14: 9 | B14: 0.4256 | C14: 0.5486 | D14: 85.37 | E14: 82.6
A15: 10 | B15: 0.3877 | C15: 0.6031 | D15: 86.87 | E15: 81.3
A16: 11 | B16: 0.3569 | C16: 0.5956 | D16: 87.84 | E16: 81.6
A17: 12 | B17: 0.3181 | C17: 0.5326 | D17: 89.1 | E17: 84.2
... A30: 25 | B30: 0.133 | C30: 0.6084 | D30: 95.4 | E30: 85

Sheet P4b
A1: Part 4b: L2 Regularization ONLY
A2: Part | B2: 4b | C2: Epochs | D2: 25
A3: Training Time (min) | B3: 25.98 | C3: Experiment | D3: L2 Regularization ONLY
A5: Epoch | B5: Train Loss | C5: Val Loss | D5: Train Acc (%) | E5: Val Acc (%)
A6: 1 | B6: 1.1896 | C6: 1.0519 | D6: 57.16 | E6: 62.3
A7: 2 | B7: 0.7942 | C7: 0.8266 | D7: 72.04 | E7: 70.7
A8: 3 | B8: 0.618 | C8: 0.6317 | D8: 78.38 | E8: 76.7
A9: 4 | B9: 0.4967 | C9: 0.6562 | D9: 82.52 | E9: 78
A10: 5 | B10: 0.3898 | C10: 0.6186 | D10: 86.44 | E10: 79.9
A11: 6 | B11: 0.3011 | C11: 0.64 | D11: 89.48 | E11: 80.3
A12: 7 | B12: 0.2233 | C12: 0.7346 | D12: 92.15 | E12: 79.1
A13: 8 | B13: 0.1673 | C13: 0.724 | D13: 94.34 | E13: 79
A14: 9 | B14: 0.126 | C14: 0.738 | D14: 95.66 | E14: 80
A15: 10 | B15: 0.1018 | C15: 0.8819 | D15: 96.47 | E15: 78.7
A16: 11 | B16: 0.0937 | C16: 0.9092 | D16: 96.76 | E16: 78.6
A17: 12 | B17: 0.0731 | C17: 0.976 | D17: 97.46 | E17: 78.9
... A30: 25 | B30: 0.0297 | C30: 1.0391 | D30: 98.98 | E30: 80.9

Sheet P4c
A1: Part 4c: Data Augmentation ONLY
A2: Part | B2: 4c | C2: Epochs | D2: 25
A3: Training Time (min) | B3: 36.08 | C3: Experiment | D3: Data Augmentation ONLY
A5: Epoch | B5: Train Loss | C5: Val Loss | D5: Train Acc (%) | E5: Val Acc (%)
A6: 1 | B6: 1.3491 | C6: 1.1049 | D6: 51.01 | E6: 59.4
A7: 2 | B7: 0.9426 | C7: 1.2051 | D7: 66.51 | E7: 60.5
A8: 3 | B8: 0.7904 | C8: 0.8037 | D8: 72.03 | E8: 73.2
A9: 4 | B9: 0.6871 | C9: 0.6464 | D9: 76.03 | E9: 78.5
A10: 5 | B10: 0.6247 | C10: 0.6101 | D10: 78.22 | E10: 81.2
A11: 6 | B11: 0.5788 | C11: 0.5787 | D11: 79.81 | E11: 81.6
A12: 7 | B12: 0.5406 | C12: 0.5189 | D12: 81.26 | E12: 82.5
A13: 8 | B13: 0.5048 | C13: 0.5424 | D13: 82.6 | E13: 82.4
A14: 9 | B14: 0.4738 | C14: 0.5664 | D14: 83.67 | E14: 80.9
A15: 10 | B15: 0.4506 | C15: 0.5097 | D15: 84.31 | E15: 83.1
A16: 11 | B16: 0.4341 | C16: 0.4552 | D16: 84.93 | E16: 84.9
A17: 12 | B17: 0.4092 | C17: 0.4568 | D17: 85.61 | E17: 84.5
... A30: 25 | B30: 0.2353 | C30: 0.3956 | D30: 91.73 | E30: 88.4

Sheet P5
A1: Part 5: Combined Regularization (Dropout + L2 + Augmentation + BatchNorm)
A2: Part | B2: 5 | C2: Epochs | D2: 50
A3: Training Time (min) | B3: 84.13 | C3: Experiment | D3: Combined Regularization (Dropout + L2 + Augmentation + BatchNorm)
A5: Epoch | B5: Train Loss | C5: Val Loss | D5: Train Acc (%) | E5: Val Acc (%)
A6: 1 | B6: 1.5426 | C6: 1.306 | D6: 43.57 | E6: 55.8
A7: 2 | B7: 1.1676 | C7: 0.9928 | D7: 58.6 | E7: 64.5
A8: 3 | B8: 0.9904 | C8: 0.7829 | D8: 65.55 | E8: 73.2
A9: 4 | B9: 0.8845 | C9: 0.7006 | D9: 69.65 | E9: 74.8
A10: 5 | B10: 0.8136 | C10: 0.6751 | D10: 72.28 | E10: 76.8
A11: 6 | B11: 0.7509 | C11: 0.5992 | D11: 74.38 | E11: 79
A12: 7 | B12: 0.7137 | C12: 0.6302 | D12: 75.79 | E12: 79.6
A13: 8 | B13: 0.6818 | C13: 0.5345 | D13: 76.84 | E13: 81.2
A14: 9 | B14: 0.6388 | C14: 0.5269 | D14: 78.27 | E14: 81.1
A15: 10 | B15: 0.6212 | C15: 0.5205 | D15: 78.71 | E15: 82.2
A16: 11 | B16: 0.5971 | C16: 0.5336 | D16: 79.68 | E16: 82.2
A17: 12 | B17: 0.5763 | C17: 0.4742 | D17: 80.55 | E17: 83.5
... A55: 50 | B55: 0.2787 | C55: 0.328 | D55: 90.43 | E55: 89.7

Sheet P6a
A1: Part 6a: Adv. Augmentation (Cut-out + Label Smoothing)
A2: Part | B2: 6a | C2: Epochs | D2: 50
A3: Training Time (min) | B3: 18.88 | C3: Experiment | D3: Adv. Augmentation (Cut-out + Label Smoothing)
A5: Epoch | B5: Train Loss | C5: Val Loss | D5: Train Acc (%) | E5: Val Acc (%)
A6: 1 | B6: 1.7343 | C6: 1.4187 | D6: 42.63 | E6: 58.4
A7: 2 | B7: 1.471 | C7: 1.3512 | D7: 56.44 | E7: 63.6
A8: 3 | B8: 1.3498 | C8: 1.29 | D8: 62.93 | E8: 64.2
A9: 4 | B9: 1.2738 | C9: 1.1163 | D9: 66.33 | E9: 72.4
A10: 5 | B10: 1.217 | C10: 1.0853 | D10: 69.44 | E10: 74.2
A11: 6 | B11: 1.177 | C11: 1.0615 | D11: 71.03 | E11: 74.9
A12: 7 | B12: 1.1445 | C12: 0.9878 | D12: 72.53 | E12: 79
A13: 8 | B13: 1.1145 | C13: 0.9838 | D13: 73.93 | E13: 79.5
A14: 9 | B14: 1.0913 | C14: 0.9987 | D14: 75.19 | E14: 77.7
A15: 10 | B15: 1.0754 | C15: 0.9518 | D15: 75.99 | E15: 79.9
A16: 11 | B16: 1.0546 | C16: 0.9292 | D16: 77.15 | E16: 82.2
A17: 12 | B17: 1.0451 | C17: 0.9049 | D17: 77.09 | E17: 82.4
... A55: 50 | B55: 0.8154 | C55: 0.7627 | D55: 87.63 | E55: 89

Sheet P6b
A1: Part 6b: LR Scheduler (Cosine Annealing with Warm Restarts)
A2: Part | B2: 6b | C2: Epochs | D2: 50
A3: Training Time (min) | B3: 47.55 | C3: Experiment | D3: LR Scheduler (Cosine Annealing with Warm Restarts)
A5: Epoch | B5: Train Loss | C5: Val Loss | D5: Train Acc (%) | E5: Val Acc (%)
A6: 1 | B6: 1.6019 | C6: 1.3762 | D6: 40.71 | E6: 49
A7: 2 | B7: 1.2332 | C7: 1.1386 | D7: 55.82 | E7: 61.2
A8: 3 | B8: 1.0458 | C8: 0.8209 | D8: 63.3 | E8: 71.7
A9: 4 | B9: 0.9082 | C9: 0.73 | D9: 68.71 | E9: 75.4
A10: 5 | B10: 0.8104 | C10: 0.6446 | D10: 72.05 | E10: 78.6
A11: 6 | B11: 0.7304 | C11: 0.5746 | D11: 75.05 | E11: 80
A12: 7 | B12: 0.6654 | C12: 0.5275 | D12: 77.31 | E12: 81.7
A13: 8 | B13: 0.6137 | C13: 0.5004 | D13: 79.06 | E13: 83.3
A14: 9 | B14: 0.5792 | C14: 0.4874 | D14: 80.31 | E14: 84.1
A15: 10 | B15: 0.5603 | C15: 0.4814 | D15: 80.91 | E15: 83.7
A16: 11 | B16: 0.7597 | C16: 0.6521 | D16: 74.31 | E16: 77.6
A17: 12 | B17: 0.7019 | C17: 0.5843 | D17: 76.24 | E17: 79.8
... A55: 50 | B55: 0.2603 | C55: 0.3053 | D55: 91.03 | E55: 90.1

Sheet P6c
A1: Part 6c: Stride 2 Down-sampling (No MaxPool)
A2: Part | B2: 6c | C2: Epochs | D2: 50
A3: Training Time (min) | B3: 36.45 | C3: Experiment | D3: Stride 2 Down-sampling (No MaxPool)
A5: Epoch | B5: Train Loss | C5: Val Loss | D5: Train Acc (%) | E5: Val Acc (%)
A6: 1 | B6: 1.605 | C6: 1.2177 | D6: 40.99 | E6: 55.8
A7: 2 | B7: 1.251 | C7: 1.0597 | D7: 55.42 | E7: 61.6
A8: 3 | B8: 1.0911 | C8: 0.8856 | D8: 61.74 | E8: 68.3
A9: 4 | B9: 0.9806 | C9: 0.8113 | D9: 65.79 | E9: 72
A10: 5 | B10: 0.9004 | C10: 0.746 | D10: 68.79 | E10: 75.1
A11: 6 | B11: 0.8324 | C11: 0.6757 | D11: 71.51 | E11: 77.1
A12: 7 | B12: 0.7853 | C12: 0.6411 | D12: 73.01 | E12: 77.4
A13: 8 | B13: 0.7414 | C13: 0.5926 | D13: 74.54 | E13: 78.7
A14: 9 | B14: 0.7141 | C14: 0.6016 | D14: 75.57 | E14: 79.3
A15: 10 | B15: 0.6814 | C15: 0.5847 | D15: 76.76 | E15: 79.8
A16: 11 | B16: 0.6603 | C16: 0.5525 | D16: 77.66 | E16: 80.1
A17: 12 | B17: 0.6326 | C17: 0.5171 | D17: 78.33 | E17: 80.7
... A55: 50 | B55: 0.3314 | C55: 0.3622 | D55: 88.52 | E55: 88.5

Sheet P6d
A1: Part 6d: Global Average Pooling (Replacing FC Layer)
A2: Part | B2: 6d | C2: Epochs | D2: 50
A3: Training Time (min) | B3: 22.9 | C3: Experiment | D3: Global Average Pooling (Replacing FC Layer)
A5: Epoch | B5: Train Loss | C5: Val Loss | D5: Train Acc (%) | E5: Val Acc (%)
A6: 1 | B6: 1.3781 | C6: 1.2716 | D6: 49.36 | E6: 55.7
A7: 2 | B7: 1.0206 | C7: 1.0296 | D7: 63.48 | E7: 65
A8: 3 | B8: 0.871 | C8: 0.7835 | D8: 69.15 | E8: 74.3
A9: 4 | B9: 0.7724 | C9: 0.6572 | D9: 72.75 | E9: 76.4
A10: 5 | B10: 0.7166 | C10: 0.6127 | D10: 74.76 | E10: 80.5
A11: 6 | B11: 0.6703 | C11: 0.6218 | D11: 76.52 | E11: 78.7
A12: 7 | B12: 0.6358 | C12: 0.5617 | D12: 77.76 | E12: 81.7
A13: 8 | B13: 0.6012 | C13: 0.5484 | D13: 78.86 | E13: 81
A14: 9 | B14: 0.5752 | C14: 0.5174 | D14: 79.91 | E14: 82.1
A15: 10 | B15: 0.5505 | C15: 0.5438 | D15: 80.66 | E15: 80.8
A16: 11 | B16: 0.5335 | C16: 0.4698 | D16: 81.26 | E16: 84.9
A17: 12 | B17: 0.5128 | C17: 0.4608 | D17: 82.01 | E17: 83.1
... A55: 50 | B55: 0.2441 | C55: 0.3608 | D55: 91.23 | E55: 89.5

Sheet Graphs
A1: Graphs for CIFAR-10 ConvNet experiments
A2: Final model selected by best validation accuracy: P6b — LR Scheduler (Cosine Annealing with Warm Restarts) (90.4%).
A4: Epoch | B4: Train Acc (%) | C4: Val Acc (%)
A5: 1 | B5: 35.72 | C5: 48.5
A6: 2 | B6: 54.33 | C6: 59.5
A7: 3 | B7: 63.66 | C7: 66.5
A8: 4 | B8: 69.19 | C8: 68.2
A9: 5 | B9: 73.66 | C9: 69.8
A10: 6 | B10: 77.59 | C10: 72.6
A11: 7 | B11: 80.91 | C11: 72.9
A12: 8 | B12: 84.17 | C12: 74.4
A13: 9 | B13: 86.22 | C13: 76
A14: 10 | B14: 89.55 | C14: 75.7
A15: 11 | B15: 91.13 | C15: 73.9
A16: 12 | B16: 93.09 | C16: 74.8
... A29: 25 | B29: 97.37 | C29: 73.7
A34: Model | B34: Best Val Acc (%) | C34: Training Time (min)
A35: Raw VGG | B35: 76 | C35: 20.62
A36: Dropout | B36: 85.3 | C36: 13.77
A37: Weight decay | B37: 82.9 | C37: 25.98
A38: Augmentation | B38: 88.4 | C38: 36.08
A39: Combined | B39: 89.7 | C39: 84.13
A45: Model | B45: Best Val Acc (%) | C45: Training Time (min)
A46: Combined | B46: 89.7 | C46: 84.13
A47: Advanced augmentation | B47: 89 | C47: 18.88
A48: Learning-rate scheduler | B48: 90.4 | C48: 47.55
A49: Downsampling | B49: 88.8 | C49: 36.45
A50: Global average pooling | B50: 90.1 | C50: 22.9
A56: Epoch | B56: Train Acc (%) | C56: Val Acc (%) | E56: Epoch | F56: Train Loss | G56: Val Loss
A57: 1 | B57: 40.71 | C57: 49 | E57: 1 | F57: 1.6019 | G57: 1.3762
A58: 2 | B58: 55.82 | C58: 61.2 | E58: 2 | F58: 1.2332 | G58: 1.1386
A59: 3 | B59: 63.3 | C59: 71.7 | E59: 3 | F59: 1.0458 | G59: 0.8209
A60: 4 | B60: 68.71 | C60: 75.4 | E60: 4 | F60: 0.9082 | G60: 0.73
A61: 5 | B61: 72.05 | C61: 78.6 | E61: 5 | F61: 0.8104 | G61: 0.6446
A62: 6 | B62: 75.05 | C62: 80 | E62: 6 | F62: 0.7304 | G62: 0.5746
A63: 7 | B63: 77.31 | C63: 81.7 | E63: 7 | F63: 0.6654 | G63: 0.5275
A64: 8 | B64: 79.06 | C64: 83.3 | E64: 8 | F64: 0.6137 | G64: 0.5004
A65: 9 | B65: 80.31 | C65: 84.1 | E65: 9 | F65: 0.5792 | G65: 0.4874
A66: 10 | B66: 80.91 | C66: 83.7 | E66: 10 | F66: 0.5603 | G66: 0.4814
A67: 11 | B67: 74.31 | C67: 77.6 | E67: 11 | F67: 0.7597 | G67: 0.6521
...
